<?xml version="1.0"?>

<!-- XML namespaces -->
<robot xmlns:xacro="http://ros.org/wiki/xacro">

  <include filename="$(find pr2_description)/urdf/common.xacro" />

  <!-- ============================   Upper Arm   ============================ -->
  <!-- Includes elbow flex, FA roll joints in macros below -->
  <xacro:macro name="prmini_upper_arm_v0" params="side parent reflect">
    <joint name="${side}_upper_arm_joint" type="fixed">
      <origin xyz="0 0 0" rpy="0 0 0" />
      <parent link="${parent}"/>
      <child link="${side}_upper_arm_link"/>
    </joint>
    <link name="${side}_upper_arm_link">
      <visual>
        <origin xyz="0 0 0" rpy="0 0 0" />
        <geometry>
          <mesh filename="package://prmini_defs/meshes/upper_arm_v0/upper_arm.stl"  />
        </geometry>
        <material name="Green" />
      </visual>
      <collision>
        <origin xyz="0 0 0" rpy="0 0 0" />
        <geometry>
          <mesh filename="package://prmini_defs/meshes/upper_arm_v0/upper_arm.stl"  />
        </geometry>
      </collision>
    </link>

    <!-- Elbow flex, FA roll macros -->
    <xacro:prmini_forearm_roll_v0 side="${side}" parent="${side}_elbow_flex_link" reflect="${reflect}" />
    <xacro:prmini_elbow_flex_v0 side="${side}" parent="${side}_upper_arm_link" reflect="${reflect}" />
  </xacro:macro>

  <xacro:macro name="prmini_elbow_flex_v0" params="side parent reflect">
    <!-- Elbow flex -->
    <joint name="${side}_elbow_flex_joint" type="revolute">
      <axis xyz="0 1 0" />
      <!-- Note: Overtravel limits are 140, -7 degrees instead of 133, 0 -->
      <limit lower="-2.3213" upper="0.00" effort="30" velocity="${VELOCITY_LIMIT_SCALE*5.5}" /> <!-- alpha tested velocity and effort limits -->
      <safety_controller k_position="100" k_velocity="3" soft_lower_limit="${-2.3213+0.2}" soft_upper_limit="${0.00-0.15}" />
      <calibration falling="${-1.1606 + cal_r_elbow_flex_flag}"/>
      <dynamics damping="1.0" />
      <origin xyz="0.2474 0 0" rpy="0 0 0" />
      <parent link="${parent}"/>
      <child link="${side}_elbow_flex_link"/>
    </joint>
    <link name="${side}_elbow_flex_link">
      <visual>
        <origin xyz="0 0 0" rpy="0 0 0" />
        <geometry>
          <mesh filename="package://prmini_defs/meshes/upper_arm_v0/elbow_flex.stl"  />
        </geometry>
        <material name="White" />
      </visual>
      <collision>
        <origin xyz="0 0 0" rpy="0 0 0" />
        <geometry>
          <mesh filename="package://prmini_defs/meshes/upper_arm_v0/elbow_flex.stl"  />
        </geometry>
      </collision>
    </link>
  </xacro:macro>
  
  <!-- FA roll joint only -->
  <xacro:macro name="prmini_forearm_roll_v0" params="side parent reflect">
    <!-- forearm_roll_link is a fictitious link internal to elbow_flex_link, provides an attachment point for the actual forearm -->
    <joint name="${side}_forearm_roll_joint" type="continuous">
      <axis xyz="1 0 0" />
      <limit effort="30" velocity="${VELOCITY_LIMIT_SCALE*6}" /> <!-- alpha tested velocity and effort limits -->
      <safety_controller k_velocity="1" />
      <calibration rising="${0.0 + cal_r_forearm_roll_flag}" />
      <dynamics damping="0.1" />
      <origin xyz="0 0 0" rpy="0 0 0" />
      <parent link="${parent}"/>
      <child link="${side}_forearm_roll_link"/>
    </joint>
    <link name="${side}_forearm_roll_link">
    </link>

  </xacro:macro>

</robot>
